Workbook

Sheet Cover

Sheet Case Study I
B5: Case Study: Company XYZ has its headcount spread across 2 locations: Location A and Location B. The CFO has asked your team to evaluate whether the company should transition work from Location A to Location B to reduce it's overall cost of running the business. Based on the data provided below, evaluate the recommendation that you will provide to the CFO. Prepare an excel output that can be used to explain your recommendation to the senior management. Please include any assumptions that you may take into account in your analysis.
B7: Monthly labor rate card across levels | H7: Current FTE (Headcount)
B8: Level | C8: Location A | D8: Location B | H8: Level | I8: Location A | J8: Location B
B9: Manager | C9: 15000 | D9: 14900 | H9: Manager | I9: 1
B10: Sr. Team Lead | C10: 12000 | D10: 11700 | H10: Sr. Team Lead | I10: 2 | J10: 3
B11: Team Lead | C11: 10000 | D11: 8850 | H11: Team Lead | I11: 3 | J11: 5
B12: Sr. Analyst II | C12: 8000 | D12: 7000 | H12: Sr. Analyst II | I12: 5 | J12: 8
B13: Sr. Analyst I | C13: 6000 | D13: 5300 | H13: Sr. Analyst I | I13: 7 | J13: 14
B14: Analyst II | C14: 4500 | D14: 4000 | H14: Analyst II | I14: 14 | J14: 45
B15: Analyst I | C15: 2500 | D15: 2200 | H15: Analyst I | I15: 23 | J15: 25
B16: Analyst I - Night Shift | C16: 3200 | D16: 2750 | H16: Analyst I - Night Shift | I16: 0 | J16: 0
H17: Total FTEs | I17: 55 | J17: 100
B19: Additional Notes
B20: - For every FTE transitioned to Location B, there will be a one-time infrastructure cost of $3,500 - Every FTE transitioned to Location B will be paid a one-time retention bonus of $2,000, except 'Manager' and 'Sr. Team Lead's' level FTEs who will get a one-time retention bonus of $3,000 - There will be an additional fixed recurring project management overhead cost of $105 per month for every FTE added to location B - The company will have to hire 2 new FTEs (Analyst I - Night Shift) at Location B; their monthly transportation cost of $250/FTE will be borne by the company - The rates at location B will be hiked by 5% for all the employees of the company - Assume all other fixed and variable costs are the same in both locations - Focus on analyzing the profitability impact over 3 years
B22: Make sure you don't paste formulas as values

Sheet Case Study II
B5: Case Study: Your company operates a global rewards program where participants from different countries earn rewards in their local currency based on performance. The finance team needs an excel-based analysis to find the following: 1. Identify highest earner in every country and overall 2. Calculate total rewards for each country in their local currency and USD both 3. Calculate rewards for each participant in USD 4. Analyze payment delays (if any) (Consider the date the incentives are being sent as - 3/25/2025) 5. Analyze and highlight budget constraints (if any) for each country (Refer to the note in next section for more details) 6. Calculate the total amount and no. of interview rewards for each country as well as overall in USD 7. Summarize the data in dashboard
B6: Additional Notes
B7: - The finance team should be intimated if the budget exceeds the following: Budget Limits USA - USD 15,000 India - INR 1,00,000 UK - GBP 4,000 Australia - AUD 3,000 Spain - EURO 4,000 Netherlands - EURO 4,000 Germany - EURO 4,000 Canada - CAD 2,500
B9: Dataset | I9: Reference Table
B10: Employee ID | C10: Country | D10: Activity Score Points | E10: Gift Type | F10: Eligibility % | G10: Due Date | I10: Country | J10: Local currency | K10: Exchange rate to USD | L10: Reward per point (Local Currency)
B11: E001 | C11: USA | D11: 120 | E11: Interview | F11: 0.75 | G11: 45735 | I11: USA | J11: USD | K11: 1 | L11: 5
B12: E002 | C12: India | D12: 300 | E12: Survey | F12: 1 | G12: 45742 | I12: India | J12: INR | K12: 0.012 | L12: 40
B13: E003 | C13: UK | D13: 180 | E13: Interview | F13: 1 | G13: 45742 | I13: UK | J13: GBP | K13: 1.25 | L13: 3.5
B14: E004 | C14: Australia | D14: 100 | E14: Survey | F14: 1 | G14: 45747 | I14: Australia | J14: AUD | K14: 0.57 | L14: 4.5
B15: E005 | C15: Spain | D15: 190 | E15: Survey | F15: 0.5 | G15: 45746 | I15: Spain | J15: EUR | K15: 1.08 | L15: 3
B16: E006 | C16: Netherlands | D16: 210 | E16: Survey | F16: 0.25 | G16: 45745 | I16: Netherlands | J16: EUR | K16: 1.08 | L16: 3.5
B17: E007 | C17: Germany | D17: 200 | E17: Interview | F17: 0.25 | G17: 45747 | I17: Germany | J17: EUR | K17: 1.08 | L17: 4
B18: E008 | C18: Canada | D18: 90 | E18: Interview | F18: 1 | G18: 45742 | I18: Canada | J18: CAD | K18: 0.75 | L18: 4
B19: E009 | C19: India | D19: 80 | E19: Survey | F19: 0.75 | G19: 45742
B20: E010 | C20: UK | D20: 243 | E20: Interview | F20: 0.25 | G20: 45742
B21: E011 | C21: Australia | D21: 231 | E21: Interview | F21: 0.25 | G21: 45742
B22: E012 | C22: Australia | D22: 130 | E22: Interview | F22: 0.5 | G22: 45742
B23: E013 | C23: Spain | D23: 167 | E23: Survey | F23: 0.75 | G23: 45732
B24: E014 | C24: USA | D24: 103 | E24: Survey | F24: 0.5 | G24: 45732
B25: E015 | C25: India | D25: 180 | E25: Survey | F25: 0.5 | G25: 45732
B26: E016 | C26: India | D26: 105 | E26: Interview | F26: 1 | G26: 45732
B27: E017 | C27: UK | D27: 117 | E27: Survey | F27: 0.75 | G27: 45732
B28: E018 | C28: Australia | D28: 120 | E28: Interview | F28: 0.75 | G28: 45742
B29: E019 | C29: Germany | D29: 235 | E29: Survey | F29: 1 | G29: 45742
B30: E020 | C30: Netherlands | D30: 172 | E30: Survey | F30: 1 | G30: 45738
... B217: E207 | C217: Netherlands | D217: 125 | E217: Interview | F217: 0.5 | G217: 45741

Sheet Back Cover

Sheet CS I - Solution
A1: Case Study I – Transition Cost Model (3-year)
A3: Transition percent of Location A moved to Location B | B3: 1
A4: Include 2 new Analyst I - Night Shift hires? | B4: Yes
A5: Analysis horizon (months) | B5: 36
A6: Project mgmt overhead per added FTE (monthly) | B6: 105
A7: Retention bonus per moved FTE – Manager/Sr TL | B7: 3000
A8: Retention bonus per moved FTE – Others | B8: 2000
A9: Infrastructure cost per moved FTE (one-time) | B9: 3500
A10: Transportation per new night-shift FTE (monthly) | B10: 250
A11: Location B rate hike | B11: 0.05
A14: Level | B14: A Headcount | C14: B Headcount | D14: A Rate | E14: B Rate (base) | F14: B Rate (5% hike) | G14: Moved to B (FTE) | H14: New A Headcount | I14: New B Headcount | J14: Added to B (FTE) | K14: One-time Retention | L14: One-time Infrastructure | M14: Monthly Transportation
A15: Manager | B15: ='Case Study I'!C9 | C15: ='Case Study I'!D9 | D15: ='Case Study I'!C9 | E15: ='Case Study I'!D9 | F15: =E15*(1+$B$11) | G15: =B15*$B$3 | H15: =B15-G15 | I15: =C15+G15+IF(AND($A15='Analyst I - Night Shift',$B$4='Yes'),2,0) | J15: =G15+IF(AND($A15='Analyst I - Night Shift',$B$4='Yes'),2,0) | K15: =IF(OR($A15='Manager',$A15='Sr. Team Lead'),$B$7,$B$8)*G15 | L15: =$B$9*G15 | M15: =IF($A15='Analyst I - Night Shift',IF($B$4='Yes',2,0)*$B$10,0)
A16: Sr. Team Lead | B16: ='Case Study I'!C10 | C16: ='Case Study I'!D10 | D16: ='Case Study I'!C10 | E16: ='Case Study I'!D10 | F16: =E16*(1+$B$11) | G16: =B16*$B$3 | H16: =B16-G16 | I16: =C16+G16+IF(AND($A16='Analyst I - Night Shift',$B$4='Yes'),2,0) | J16: =G16+IF(AND($A16='Analyst I - Night Shift',$B$4='Yes'),2,0) | K16: =IF(OR($A16='Manager',$A16='Sr. Team Lead'),$B$7,$B$8)*G16 | L16: =$B$9*G16 | M16: =IF($A16='Analyst I - Night Shift',IF($B$4='Yes',2,0)*$B$10,0)
A17: Team Lead | B17: ='Case Study I'!C11 | C17: ='Case Study I'!D11 | D17: ='Case Study I'!C11 | E17: ='Case Study I'!D11 | F17: =E17*(1+$B$11) | G17: =B17*$B$3 | H17: =B17-G17 | I17: =C17+G17+IF(AND($A17='Analyst I - Night Shift',$B$4='Yes'),2,0) | J17: =G17+IF(AND($A17='Analyst I - Night Shift',$B$4='Yes'),2,0) | K17: =IF(OR($A17='Manager',$A17='Sr. Team Lead'),$B$7,$B$8)*G17 | L17: =$B$9*G17 | M17: =IF($A17='Analyst I - Night Shift',IF($B$4='Yes',2,0)*$B$10,0)
A18: Sr. Analyst II | B18: ='Case Study I'!C12 | C18: ='Case Study I'!D12 | D18: ='Case Study I'!C12 | E18: ='Case Study I'!D12 | F18: =E18*(1+$B$11) | G18: =B18*$B$3 | H18: =B18-G18 | I18: =C18+G18+IF(AND($A18='Analyst I - Night Shift',$B$4='Yes'),2,0) | J18: =G18+IF(AND($A18='Analyst I - Night Shift',$B$4='Yes'),2,0) | K18: =IF(OR($A18='Manager',$A18='Sr. Team Lead'),$B$7,$B$8)*G18 | L18: =$B$9*G18 | M18: =IF($A18='Analyst I - Night Shift',IF($B$4='Yes',2,0)*$B$10,0)
A19: Sr. Analyst I | B19: ='Case Study I'!C13 | C19: ='Case Study I'!D13 | D19: ='Case Study I'!C13 | E19: ='Case Study I'!D13 | F19: =E19*(1+$B$11) | G19: =B19*$B$3 | H19: =B19-G19 | I19: =C19+G19+IF(AND($A19='Analyst I - Night Shift',$B$4='Yes'),2,0) | J19: =G19+IF(AND($A19='Analyst I - Night Shift',$B$4='Yes'),2,0) | K19: =IF(OR($A19='Manager',$A19='Sr. Team Lead'),$B$7,$B$8)*G19 | L19: =$B$9*G19 | M19: =IF($A19='Analyst I - Night Shift',IF($B$4='Yes',2,0)*$B$10,0)
A20: Analyst II | B20: ='Case Study I'!C14 | C20: ='Case Study I'!D14 | D20: ='Case Study I'!C14 | E20: ='Case Study I'!D14 | F20: =E20*(1+$B$11) | G20: =B20*$B$3 | H20: =B20-G20 | I20: =C20+G20+IF(AND($A20='Analyst I - Night Shift',$B$4='Yes'),2,0) | J20: =G20+IF(AND($A20='Analyst I - Night Shift',$B$4='Yes'),2,0) | K20: =IF(OR($A20='Manager',$A20='Sr. Team Lead'),$B$7,$B$8)*G20 | L20: =$B$9*G20 | M20: =IF($A20='Analyst I - Night Shift',IF($B$4='Yes',2,0)*$B$10,0)
A21: Analyst I | B21: ='Case Study I'!C15 | C21: ='Case Study I'!D15 | D21: ='Case Study I'!C15 | E21: ='Case Study I'!D15 | F21: =E21*(1+$B$11) | G21: =B21*$B$3 | H21: =B21-G21 | I21: =C21+G21+IF(AND($A21='Analyst I - Night Shift',$B$4='Yes'),2,0) | J21: =G21+IF(AND($A21='Analyst I - Night Shift',$B$4='Yes'),2,0) | K21: =IF(OR($A21='Manager',$A21='Sr. Team Lead'),$B$7,$B$8)*G21 | L21: =$B$9*G21 | M21: =IF($A21='Analyst I - Night Shift',IF($B$4='Yes',2,0)*$B$10,0)
A22: Analyst I - Night Shift | B22: ='Case Study I'!C16 | C22: ='Case Study I'!D16 | D22: ='Case Study I'!C16 | E22: ='Case Study I'!D16 | F22: =E22*(1+$B$11) | G22: =B22*$B$3 | H22: =B22-G22 | I22: =C22+G22+IF(AND($A22='Analyst I - Night Shift',$B$4='Yes'),2,0) | J22: =G22+IF(AND($A22='Analyst I - Night Shift',$B$4='Yes'),2,0) | K22: =IF(OR($A22='Manager',$A22='Sr. Team Lead'),$B$7,$B$8)*G22 | L22: =$B$9*G22 | M22: =IF($A22='Analyst I - Night Shift',IF($B$4='Yes',2,0)*$B$10,0)
A23: TOTALS | B23: =SUM(B15:B22) | C23: =SUM(C15:C22) | D23: =SUM(D15:D22) | E23: =SUM(E15:E22) | F23: =SUM(F15:F22) | G23: =SUM(G15:G22) | H23: =SUM(H15:H22) | I23: =SUM(I15:I22) | ... M23: =SUM(M15:M22)
A26: Baseline monthly wage cost | B26: =SUMPRODUCT(B15:B22,D15:D22)+SUMPRODUCT(C15:C22,F15:F22)
A27: Post-move monthly wage cost | B27: =SUMPRODUCT(H15:H22,D15:D22)+SUMPRODUCT(I15:I22,F15:F22)
A28: Monthly overhead (added FTEs * $105) | B28: =$B$6*J23
A29: Monthly transportation (new hires only) | B29: =M23
A30: Post-move monthly total | B30: =B27+B28+B29
A31: Monthly savings vs baseline | B31: =B26-B30
A32: One-time retention + infrastructure | B32: =K23+L23
A33: 3-year baseline cost | B33: =B26*$B$5
A34: 3-year post-move cost | B34: =B30*$B$5+B32
A35: 3-year net savings (positive = good) | B35: =B33-B34
A36: Breakeven months (one-time / monthly savings) | B36: =IF(B31>0,B32/B31,NA())
A39: Recommendation | B39: =IF(B35>0, 'Move FTEs from A to B', 'Do NOT move')

Sheet CS II - Calc
A1: Employee ID | B1: Country | C1: Activity Score Points | D1: Gift Type | E1: Eligibility % | F1: Due Date | G1: Local currency | H1: Exch to USD | I1: Reward/pt (Local) | J1: Reward Local | K1: Reward USD | L1: Is Interview | M1: Status | N1: Days Delay | O1: Send Date
A2: ='Case Study II'!B11 | B2: ='Case Study II'!I11 | C2: ='Case Study II'!D11 | D2: ='Case Study II'!E11 | E2: ='Case Study II'!F11 | F2: ='Case Study II'!G11 | G2: =INDEX('Case Study II'!I11:L18, MATCH(B2, INDEX('Case Study II'!I11:L18,,1), 0), 2) | H2: =INDEX('Case Study II'!I11:L18, MATCH(B2, INDEX('Case Study II'!I11:L18,,1), 0), 3) | I2: =INDEX('Case Study II'!I11:L18, MATCH(B2, INDEX('Case Study II'!I11:L18,,1), 0), 4) | J2: =C2*E2*I2 | K2: =J2*H2 | L2: =IF(D2='Interview',1,0) | M2: =IF(O2>F2,'Delayed','On time') | N2: =IF(O2>F2,O2-F2,0) | O2: =DATE(2025,3,25)
A3: ='Case Study II'!B12 | B3: ='Case Study II'!I12 | C3: ='Case Study II'!D12 | D3: ='Case Study II'!E12 | E3: ='Case Study II'!F12 | F3: ='Case Study II'!G12 | G3: =INDEX('Case Study II'!I11:L18, MATCH(B3, INDEX('Case Study II'!I11:L18,,1), 0), 2) | H3: =INDEX('Case Study II'!I11:L18, MATCH(B3, INDEX('Case Study II'!I11:L18,,1), 0), 3) | I3: =INDEX('Case Study II'!I11:L18, MATCH(B3, INDEX('Case Study II'!I11:L18,,1), 0), 4) | J3: =C3*E3*I3 | K3: =J3*H3 | L3: =IF(D3='Interview',1,0) | M3: =IF(O3>F3,'Delayed','On time') | N3: =IF(O3>F3,O3-F3,0) | O3: =DATE(2025,3,25)
A4: ='Case Study II'!B13 | B4: ='Case Study II'!I13 | C4: ='Case Study II'!D13 | D4: ='Case Study II'!E13 | E4: ='Case Study II'!F13 | F4: ='Case Study II'!G13 | G4: =INDEX('Case Study II'!I11:L18, MATCH(B4, INDEX('Case Study II'!I11:L18,,1), 0), 2) | H4: =INDEX('Case Study II'!I11:L18, MATCH(B4, INDEX('Case Study II'!I11:L18,,1), 0), 3) | I4: =INDEX('Case Study II'!I11:L18, MATCH(B4, INDEX('Case Study II'!I11:L18,,1), 0), 4) | J4: =C4*E4*I4 | K4: =J4*H4 | L4: =IF(D4='Interview',1,0) | M4: =IF(O4>F4,'Delayed','On time') | N4: =IF(O4>F4,O4-F4,0) | O4: =DATE(2025,3,25)
A5: ='Case Study II'!B14 | B5: ='Case Study II'!I14 | C5: ='Case Study II'!D14 | D5: ='Case Study II'!E14 | E5: ='Case Study II'!F14 | F5: ='Case Study II'!G14 | G5: =INDEX('Case Study II'!I11:L18, MATCH(B5, INDEX('Case Study II'!I11:L18,,1), 0), 2) | H5: =INDEX('Case Study II'!I11:L18, MATCH(B5, INDEX('Case Study II'!I11:L18,,1), 0), 3) | I5: =INDEX('Case Study II'!I11:L18, MATCH(B5, INDEX('Case Study II'!I11:L18,,1), 0), 4) | J5: =C5*E5*I5 | K5: =J5*H5 | L5: =IF(D5='Interview',1,0) | M5: =IF(O5>F5,'Delayed','On time') | N5: =IF(O5>F5,O5-F5,0) | O5: =DATE(2025,3,25)
A6: ='Case Study II'!B15 | B6: ='Case Study II'!I15 | C6: ='Case Study II'!D15 | D6: ='Case Study II'!E15 | E6: ='Case Study II'!F15 | F6: ='Case Study II'!G15 | G6: =INDEX('Case Study II'!I11:L18, MATCH(B6, INDEX('Case Study II'!I11:L18,,1), 0), 2) | H6: =INDEX('Case Study II'!I11:L18, MATCH(B6, INDEX('Case Study II'!I11:L18,,1), 0), 3) | I6: =INDEX('Case Study II'!I11:L18, MATCH(B6, INDEX('Case Study II'!I11:L18,,1), 0), 4) | J6: =C6*E6*I6 | K6: =J6*H6 | L6: =IF(D6='Interview',1,0) | M6: =IF(O6>F6,'Delayed','On time') | N6: =IF(O6>F6,O6-F6,0) | O6: =DATE(2025,3,25)
A7: ='Case Study II'!B16 | B7: ='Case Study II'!I16 | C7: ='Case Study II'!D16 | D7: ='Case Study II'!E16 | E7: ='Case Study II'!F16 | F7: ='Case Study II'!G16 | G7: =INDEX('Case Study II'!I11:L18, MATCH(B7, INDEX('Case Study II'!I11:L18,,1), 0), 2) | H7: =INDEX('Case Study II'!I11:L18, MATCH(B7, INDEX('Case Study II'!I11:L18,,1), 0), 3) | I7: =INDEX('Case Study II'!I11:L18, MATCH(B7, INDEX('Case Study II'!I11:L18,,1), 0), 4) | J7: =C7*E7*I7 | K7: =J7*H7 | L7: =IF(D7='Interview',1,0) | M7: =IF(O7>F7,'Delayed','On time') | N7: =IF(O7>F7,O7-F7,0) | O7: =DATE(2025,3,25)
A8: ='Case Study II'!B17 | B8: ='Case Study II'!I17 | C8: ='Case Study II'!D17 | D8: ='Case Study II'!E17 | E8: ='Case Study II'!F17 | F8: ='Case Study II'!G17 | G8: =INDEX('Case Study II'!I11:L18, MATCH(B8, INDEX('Case Study II'!I11:L18,,1), 0), 2) | H8: =INDEX('Case Study II'!I11:L18, MATCH(B8, INDEX('Case Study II'!I11:L18,,1), 0), 3) | I8: =INDEX('Case Study II'!I11:L18, MATCH(B8, INDEX('Case Study II'!I11:L18,,1), 0), 4) | J8: =C8*E8*I8 | K8: =J8*H8 | L8: =IF(D8='Interview',1,0) | M8: =IF(O8>F8,'Delayed','On time') | N8: =IF(O8>F8,O8-F8,0) | O8: =DATE(2025,3,25)
A9: ='Case Study II'!B18 | B9: ='Case Study II'!I18 | C9: ='Case Study II'!D18 | D9: ='Case Study II'!E18 | E9: ='Case Study II'!F18 | F9: ='Case Study II'!G18 | G9: =INDEX('Case Study II'!I11:L18, MATCH(B9, INDEX('Case Study II'!I11:L18,,1), 0), 2) | H9: =INDEX('Case Study II'!I11:L18, MATCH(B9, INDEX('Case Study II'!I11:L18,,1), 0), 3) | I9: =INDEX('Case Study II'!I11:L18, MATCH(B9, INDEX('Case Study II'!I11:L18,,1), 0), 4) | J9: =C9*E9*I9 | K9: =J9*H9 | L9: =IF(D9='Interview',1,0) | M9: =IF(O9>F9,'Delayed','On time') | N9: =IF(O9>F9,O9-F9,0) | O9: =DATE(2025,3,25)
A10: ='Case Study II'!B19 | B10: ='Case Study II'!I19 | C10: ='Case Study II'!D19 | D10: ='Case Study II'!E19 | E10: ='Case Study II'!F19 | F10: ='Case Study II'!G19 | G10: =INDEX('Case Study II'!I11:L18, MATCH(B10, INDEX('Case Study II'!I11:L18,,1), 0), 2) | H10: =INDEX('Case Study II'!I11:L18, MATCH(B10, INDEX('Case Study II'!I11:L18,,1), 0), 3) | I10: =INDEX('Case Study II'!I11:L18, MATCH(B10, INDEX('Case Study II'!I11:L18,,1), 0), 4) | J10: =C10*E10*I10 | K10: =J10*H10 | L10: =IF(D10='Interview',1,0) | M10: =IF(O10>F10,'Delayed','On time') | N10: =IF(O10>F10,O10-F10,0) | O10: =DATE(2025,3,25)
A11: ='Case Study II'!B20 | B11: ='Case Study II'!I20 | C11: ='Case Study II'!D20 | D11: ='Case Study II'!E20 | E11: ='Case Study II'!F20 | F11: ='Case Study II'!G20 | G11: =INDEX('Case Study II'!I11:L18, MATCH(B11, INDEX('Case Study II'!I11:L18,,1), 0), 2) | H11: =INDEX('Case Study II'!I11:L18, MATCH(B11, INDEX('Case Study II'!I11:L18,,1), 0), 3) | I11: =INDEX('Case Study II'!I11:L18, MATCH(B11, INDEX('Case Study II'!I11:L18,,1), 0), 4) | J11: =C11*E11*I11 | K11: =J11*H11 | L11: =IF(D11='Interview',1,0) | M11: =IF(O11>F11,'Delayed','On time') | N11: =IF(O11>F11,O11-F11,0) | O11: =DATE(2025,3,25)
A12: ='Case Study II'!B21 | B12: ='Case Study II'!I21 | C12: ='Case Study II'!D21 | D12: ='Case Study II'!E21 | E12: ='Case Study II'!F21 | F12: ='Case Study II'!G21 | G12: =INDEX('Case Study II'!I11:L18, MATCH(B12, INDEX('Case Study II'!I11:L18,,1), 0), 2) | H12: =INDEX('Case Study II'!I11:L18, MATCH(B12, INDEX('Case Study II'!I11:L18,,1), 0), 3) | I12: =INDEX('Case Study II'!I11:L18, MATCH(B12, INDEX('Case Study II'!I11:L18,,1), 0), 4) | J12: =C12*E12*I12 | K12: =J12*H12 | L12: =IF(D12='Interview',1,0) | M12: =IF(O12>F12,'Delayed','On time') | N12: =IF(O12>F12,O12-F12,0) | O12: =DATE(2025,3,25)
A13: ='Case Study II'!B22 | B13: ='Case Study II'!I22 | C13: ='Case Study II'!D22 | D13: ='Case Study II'!E22 | E13: ='Case Study II'!F22 | F13: ='Case Study II'!G22 | G13: =INDEX('Case Study II'!I11:L18, MATCH(B13, INDEX('Case Study II'!I11:L18,,1), 0), 2) | H13: =INDEX('Case Study II'!I11:L18, MATCH(B13, INDEX('Case Study II'!I11:L18,,1), 0), 3) | I13: =INDEX('Case Study II'!I11:L18, MATCH(B13, INDEX('Case Study II'!I11:L18,,1), 0), 4) | J13: =C13*E13*I13 | K13: =J13*H13 | L13: =IF(D13='Interview',1,0) | M13: =IF(O13>F13,'Delayed','On time') | N13: =IF(O13>F13,O13-F13,0) | O13: =DATE(2025,3,25)
A14: ='Case Study II'!B23 | B14: ='Case Study II'!I23 | C14: ='Case Study II'!D23 | D14: ='Case Study II'!E23 | E14: ='Case Study II'!F23 | F14: ='Case Study II'!G23 | G14: =INDEX('Case Study II'!I11:L18, MATCH(B14, INDEX('Case Study II'!I11:L18,,1), 0), 2) | H14: =INDEX('Case Study II'!I11:L18, MATCH(B14, INDEX('Case Study II'!I11:L18,,1), 0), 3) | I14: =INDEX('Case Study II'!I11:L18, MATCH(B14, INDEX('Case Study II'!I11:L18,,1), 0), 4) | J14: =C14*E14*I14 | K14: =J14*H14 | L14: =IF(D14='Interview',1,0) | M14: =IF(O14>F14,'Delayed','On time') | N14: =IF(O14>F14,O14-F14,0) | O14: =DATE(2025,3,25)
A15: ='Case Study II'!B24 | B15: ='Case Study II'!I24 | C15: ='Case Study II'!D24 | D15: ='Case Study II'!E24 | E15: ='Case Study II'!F24 | F15: ='Case Study II'!G24 | G15: =INDEX('Case Study II'!I11:L18, MATCH(B15, INDEX('Case Study II'!I11:L18,,1), 0), 2) | H15: =INDEX('Case Study II'!I11:L18, MATCH(B15, INDEX('Case Study II'!I11:L18,,1), 0), 3) | I15: =INDEX('Case Study II'!I11:L18, MATCH(B15, INDEX('Case Study II'!I11:L18,,1), 0), 4) | J15: =C15*E15*I15 | K15: =J15*H15 | L15: =IF(D15='Interview',1,0) | M15: =IF(O15>F15,'Delayed','On time') | N15: =IF(O15>F15,O15-F15,0) | O15: =DATE(2025,3,25)
A16: ='Case Study II'!B25 | B16: ='Case Study II'!I25 | C16: ='Case Study II'!D25 | D16: ='Case Study II'!E25 | E16: ='Case Study II'!F25 | F16: ='Case Study II'!G25 | G16: =INDEX('Case Study II'!I11:L18, MATCH(B16, INDEX('Case Study II'!I11:L18,,1), 0), 2) | H16: =INDEX('Case Study II'!I11:L18, MATCH(B16, INDEX('Case Study II'!I11:L18,,1), 0), 3) | I16: =INDEX('Case Study II'!I11:L18, MATCH(B16, INDEX('Case Study II'!I11:L18,,1), 0), 4) | J16: =C16*E16*I16 | K16: =J16*H16 | L16: =IF(D16='Interview',1,0) | M16: =IF(O16>F16,'Delayed','On time') | N16: =IF(O16>F16,O16-F16,0) | O16: =DATE(2025,3,25)
A17: ='Case Study II'!B26 | B17: ='Case Study II'!I26 | C17: ='Case Study II'!D26 | D17: ='Case Study II'!E26 | E17: ='Case Study II'!F26 | F17: ='Case Study II'!G26 | G17: =INDEX('Case Study II'!I11:L18, MATCH(B17, INDEX('Case Study II'!I11:L18,,1), 0), 2) | H17: =INDEX('Case Study II'!I11:L18, MATCH(B17, INDEX('Case Study II'!I11:L18,,1), 0), 3) | I17: =INDEX('Case Study II'!I11:L18, MATCH(B17, INDEX('Case Study II'!I11:L18,,1), 0), 4) | J17: =C17*E17*I17 | K17: =J17*H17 | L17: =IF(D17='Interview',1,0) | M17: =IF(O17>F17,'Delayed','On time') | N17: =IF(O17>F17,O17-F17,0) | O17: =DATE(2025,3,25)
A18: ='Case Study II'!B27 | B18: ='Case Study II'!I27 | C18: ='Case Study II'!D27 | D18: ='Case Study II'!E27 | E18: ='Case Study II'!F27 | F18: ='Case Study II'!G27 | G18: =INDEX('Case Study II'!I11:L18, MATCH(B18, INDEX('Case Study II'!I11:L18,,1), 0), 2) | H18: =INDEX('Case Study II'!I11:L18, MATCH(B18, INDEX('Case Study II'!I11:L18,,1), 0), 3) | I18: =INDEX('Case Study II'!I11:L18, MATCH(B18, INDEX('Case Study II'!I11:L18,,1), 0), 4) | J18: =C18*E18*I18 | K18: =J18*H18 | L18: =IF(D18='Interview',1,0) | M18: =IF(O18>F18,'Delayed','On time') | N18: =IF(O18>F18,O18-F18,0) | O18: =DATE(2025,3,25)
A19: ='Case Study II'!B28 | B19: ='Case Study II'!I28 | C19: ='Case Study II'!D28 | D19: ='Case Study II'!E28 | E19: ='Case Study II'!F28 | F19: ='Case Study II'!G28 | G19: =INDEX('Case Study II'!I11:L18, MATCH(B19, INDEX('Case Study II'!I11:L18,,1), 0), 2) | H19: =INDEX('Case Study II'!I11:L18, MATCH(B19, INDEX('Case Study II'!I11:L18,,1), 0), 3) | I19: =INDEX('Case Study II'!I11:L18, MATCH(B19, INDEX('Case Study II'!I11:L18,,1), 0), 4) | J19: =C19*E19*I19 | K19: =J19*H19 | L19: =IF(D19='Interview',1,0) | M19: =IF(O19>F19,'Delayed','On time') | N19: =IF(O19>F19,O19-F19,0) | O19: =DATE(2025,3,25)
A20: ='Case Study II'!B29 | B20: ='Case Study II'!I29 | C20: ='Case Study II'!D29 | D20: ='Case Study II'!E29 | E20: ='Case Study II'!F29 | F20: ='Case Study II'!G29 | G20: =INDEX('Case Study II'!I11:L18, MATCH(B20, INDEX('Case Study II'!I11:L18,,1), 0), 2) | H20: =INDEX('Case Study II'!I11:L18, MATCH(B20, INDEX('Case Study II'!I11:L18,,1), 0), 3) | I20: =INDEX('Case Study II'!I11:L18, MATCH(B20, INDEX('Case Study II'!I11:L18,,1), 0), 4) | J20: =C20*E20*I20 | K20: =J20*H20 | L20: =IF(D20='Interview',1,0) | M20: =IF(O20>F20,'Delayed','On time') | N20: =IF(O20>F20,O20-F20,0) | O20: =DATE(2025,3,25)
A21: ='Case Study II'!B30 | B21: ='Case Study II'!I30 | C21: ='Case Study II'!D30 | D21: ='Case Study II'!E30 | E21: ='Case Study II'!F30 | F21: ='Case Study II'!G30 | G21: =INDEX('Case Study II'!I11:L18, MATCH(B21, INDEX('Case Study II'!I11:L18,,1), 0), 2) | H21: =INDEX('Case Study II'!I11:L18, MATCH(B21, INDEX('Case Study II'!I11:L18,,1), 0), 3) | I21: =INDEX('Case Study II'!I11:L18, MATCH(B21, INDEX('Case Study II'!I11:L18,,1), 0), 4) | J21: =C21*E21*I21 | K21: =J21*H21 | L21: =IF(D21='Interview',1,0) | M21: =IF(O21>F21,'Delayed','On time') | N21: =IF(O21>F21,O21-F21,0) | O21: =DATE(2025,3,25)
A22: ='Case Study II'!B31 | B22: ='Case Study II'!I31 | C22: ='Case Study II'!D31 | D22: ='Case Study II'!E31 | E22: ='Case Study II'!F31 | F22: ='Case Study II'!G31 | G22: =INDEX('Case Study II'!I11:L18, MATCH(B22, INDEX('Case Study II'!I11:L18,,1), 0), 2) | H22: =INDEX('Case Study II'!I11:L18, MATCH(B22, INDEX('Case Study II'!I11:L18,,1), 0), 3) | I22: =INDEX('Case Study II'!I11:L18, MATCH(B22, INDEX('Case Study II'!I11:L18,,1), 0), 4) | J22: =C22*E22*I22 | K22: =J22*H22 | L22: =IF(D22='Interview',1,0) | M22: =IF(O22>F22,'Delayed','On time') | N22: =IF(O22>F22,O22-F22,0) | O22: =DATE(2025,3,25)
A23: ='Case Study II'!B32 | B23: ='Case Study II'!I32 | C23: ='Case Study II'!D32 | D23: ='Case Study II'!E32 | E23: ='Case Study II'!F32 | F23: ='Case Study II'!G32 | G23: =INDEX('Case Study II'!I11:L18, MATCH(B23, INDEX('Case Study II'!I11:L18,,1), 0), 2) | H23: =INDEX('Case Study II'!I11:L18, MATCH(B23, INDEX('Case Study II'!I11:L18,,1), 0), 3) | I23: =INDEX('Case Study II'!I11:L18, MATCH(B23, INDEX('Case Study II'!I11:L18,,1), 0), 4) | J23: =C23*E23*I23 | K23: =J23*H23 | L23: =IF(D23='Interview',1,0) | M23: =IF(O23>F23,'Delayed','On time') | N23: =IF(O23>F23,O23-F23,0) | O23: =DATE(2025,3,25)
A24: ='Case Study II'!B33 | B24: ='Case Study II'!I33 | C24: ='Case Study II'!D33 | D24: ='Case Study II'!E33 | E24: ='Case Study II'!F33 | F24: ='Case Study II'!G33 | G24: =INDEX('Case Study II'!I11:L18, MATCH(B24, INDEX('Case Study II'!I11:L18,,1), 0), 2) | H24: =INDEX('Case Study II'!I11:L18, MATCH(B24, INDEX('Case Study II'!I11:L18,,1), 0), 3) | I24: =INDEX('Case Study II'!I11:L18, MATCH(B24, INDEX('Case Study II'!I11:L18,,1), 0), 4) | J24: =C24*E24*I24 | K24: =J24*H24 | L24: =IF(D24='Interview',1,0) | M24: =IF(O24>F24,'Delayed','On time') | N24: =IF(O24>F24,O24-F24,0) | O24: =DATE(2025,3,25)
A25: ='Case Study II'!B34 | B25: ='Case Study II'!I34 | C25: ='Case Study II'!D34 | D25: ='Case Study II'!E34 | E25: ='Case Study II'!F34 | F25: ='Case Study II'!G34 | G25: =INDEX('Case Study II'!I11:L18, MATCH(B25, INDEX('Case Study II'!I11:L18,,1), 0), 2) | H25: =INDEX('Case Study II'!I11:L18, MATCH(B25, INDEX('Case Study II'!I11:L18,,1), 0), 3) | I25: =INDEX('Case Study II'!I11:L18, MATCH(B25, INDEX('Case Study II'!I11:L18,,1), 0), 4) | J25: =C25*E25*I25 | K25: =J25*H25 | L25: =IF(D25='Interview',1,0) | M25: =IF(O25>F25,'Delayed','On time') | N25: =IF(O25>F25,O25-F25,0) | O25: =DATE(2025,3,25)
A26: ='Case Study II'!B35 | B26: ='Case Study II'!I35 | C26: ='Case Study II'!D35 | D26: ='Case Study II'!E35 | E26: ='Case Study II'!F35 | F26: ='Case Study II'!G35 | G26: =INDEX('Case Study II'!I11:L18, MATCH(B26, INDEX('Case Study II'!I11:L18,,1), 0), 2) | H26: =INDEX('Case Study II'!I11:L18, MATCH(B26, INDEX('Case Study II'!I11:L18,,1), 0), 3) | I26: =INDEX('Case Study II'!I11:L18, MATCH(B26, INDEX('Case Study II'!I11:L18,,1), 0), 4) | J26: =C26*E26*I26 | K26: =J26*H26 | L26: =IF(D26='Interview',1,0) | M26: =IF(O26>F26,'Delayed','On time') | N26: =IF(O26>F26,O26-F26,0) | O26: =DATE(2025,3,25)
A27: ='Case Study II'!B36 | B27: ='Case Study II'!I36 | C27: ='Case Study II'!D36 | D27: ='Case Study II'!E36 | E27: ='Case Study II'!F36 | F27: ='Case Study II'!G36 | G27: =INDEX('Case Study II'!I11:L18, MATCH(B27, INDEX('Case Study II'!I11:L18,,1), 0), 2) | H27: =INDEX('Case Study II'!I11:L18, MATCH(B27, INDEX('Case Study II'!I11:L18,,1), 0), 3) | I27: =INDEX('Case Study II'!I11:L18, MATCH(B27, INDEX('Case Study II'!I11:L18,,1), 0), 4) | J27: =C27*E27*I27 | K27: =J27*H27 | L27: =IF(D27='Interview',1,0) | M27: =IF(O27>F27,'Delayed','On time') | N27: =IF(O27>F27,O27-F27,0) | O27: =DATE(2025,3,25)
A28: ='Case Study II'!B37 | B28: ='Case Study II'!I37 | C28: ='Case Study II'!D37 | D28: ='Case Study II'!E37 | E28: ='Case Study II'!F37 | F28: ='Case Study II'!G37 | G28: =INDEX('Case Study II'!I11:L18, MATCH(B28, INDEX('Case Study II'!I11:L18,,1), 0), 2) | H28: =INDEX('Case Study II'!I11:L18, MATCH(B28, INDEX('Case Study II'!I11:L18,,1), 0), 3) | I28: =INDEX('Case Study II'!I11:L18, MATCH(B28, INDEX('Case Study II'!I11:L18,,1), 0), 4) | J28: =C28*E28*I28 | K28: =J28*H28 | L28: =IF(D28='Interview',1,0) | M28: =IF(O28>F28,'Delayed','On time') | N28: =IF(O28>F28,O28-F28,0) | O28: =DATE(2025,3,25)
A29: ='Case Study II'!B38 | B29: ='Case Study II'!I38 | C29: ='Case Study II'!D38 | D29: ='Case Study II'!E38 | E29: ='Case Study II'!F38 | F29: ='Case Study II'!G38 | G29: =INDEX('Case Study II'!I11:L18, MATCH(B29, INDEX('Case Study II'!I11:L18,,1), 0), 2) | H29: =INDEX('Case Study II'!I11:L18, MATCH(B29, INDEX('Case Study II'!I11:L18,,1), 0), 3) | I29: =INDEX('Case Study II'!I11:L18, MATCH(B29, INDEX('Case Study II'!I11:L18,,1), 0), 4) | J29: =C29*E29*I29 | K29: =J29*H29 | L29: =IF(D29='Interview',1,0) | M29: =IF(O29>F29,'Delayed','On time') | N29: =IF(O29>F29,O29-F29,0) | O29: =DATE(2025,3,25)
A30: ='Case Study II'!B39 | B30: ='Case Study II'!I39 | C30: ='Case Study II'!D39 | D30: ='Case Study II'!E39 | E30: ='Case Study II'!F39 | F30: ='Case Study II'!G39 | G30: =INDEX('Case Study II'!I11:L18, MATCH(B30, INDEX('Case Study II'!I11:L18,,1), 0), 2) | H30: =INDEX('Case Study II'!I11:L18, MATCH(B30, INDEX('Case Study II'!I11:L18,,1), 0), 3) | I30: =INDEX('Case Study II'!I11:L18, MATCH(B30, INDEX('Case Study II'!I11:L18,,1), 0), 4) | J30: =C30*E30*I30 | K30: =J30*H30 | L30: =IF(D30='Interview',1,0) | M30: =IF(O30>F30,'Delayed','On time') | N30: =IF(O30>F30,O30-F30,0) | O30: =DATE(2025,3,25)
A31: ='Case Study II'!B40 | B31: ='Case Study II'!I40 | C31: ='Case Study II'!D40 | D31: ='Case Study II'!E40 | E31: ='Case Study II'!F40 | F31: ='Case Study II'!G40 | G31: =INDEX('Case Study II'!I11:L18, MATCH(B31, INDEX('Case Study II'!I11:L18,,1), 0), 2) | H31: =INDEX('Case Study II'!I11:L18, MATCH(B31, INDEX('Case Study II'!I11:L18,,1), 0), 3) | I31: =INDEX('Case Study II'!I11:L18, MATCH(B31, INDEX('Case Study II'!I11:L18,,1), 0), 4) | J31: =C31*E31*I31 | K31: =J31*H31 | L31: =IF(D31='Interview',1,0) | M31: =IF(O31>F31,'Delayed','On time') | N31: =IF(O31>F31,O31-F31,0) | O31: =DATE(2025,3,25)
A32: ='Case Study II'!B41 | B32: ='Case Study II'!I41 | C32: ='Case Study II'!D41 | D32: ='Case Study II'!E41 | E32: ='Case Study II'!F41 | F32: ='Case Study II'!G41 | G32: =INDEX('Case Study II'!I11:L18, MATCH(B32, INDEX('Case Study II'!I11:L18,,1), 0), 2) | H32: =INDEX('Case Study II'!I11:L18, MATCH(B32, INDEX('Case Study II'!I11:L18,,1), 0), 3) | I32: =INDEX('Case Study II'!I11:L18, MATCH(B32, INDEX('Case Study II'!I11:L18,,1), 0), 4) | J32: =C32*E32*I32 | K32: =J32*H32 | L32: =IF(D32='Interview',1,0) | M32: =IF(O32>F32,'Delayed','On time') | N32: =IF(O32>F32,O32-F32,0) | O32: =DATE(2025,3,25)
A33: ='Case Study II'!B42 | B33: ='Case Study II'!I42 | C33: ='Case Study II'!D42 | D33: ='Case Study II'!E42 | E33: ='Case Study II'!F42 | F33: ='Case Study II'!G42 | G33: =INDEX('Case Study II'!I11:L18, MATCH(B33, INDEX('Case Study II'!I11:L18,,1), 0), 2) | H33: =INDEX('Case Study II'!I11:L18, MATCH(B33, INDEX('Case Study II'!I11:L18,,1), 0), 3) | I33: =INDEX('Case Study II'!I11:L18, MATCH(B33, INDEX('Case Study II'!I11:L18,,1), 0), 4) | J33: =C33*E33*I33 | K33: =J33*H33 | L33: =IF(D33='Interview',1,0) | M33: =IF(O33>F33,'Delayed','On time') | N33: =IF(O33>F33,O33-F33,0) | O33: =DATE(2025,3,25)
A34: ='Case Study II'!B43 | B34: ='Case Study II'!I43 | C34: ='Case Study II'!D43 | D34: ='Case Study II'!E43 | E34: ='Case Study II'!F43 | F34: ='Case Study II'!G43 | G34: =INDEX('Case Study II'!I11:L18, MATCH(B34, INDEX('Case Study II'!I11:L18,,1), 0), 2) | H34: =INDEX('Case Study II'!I11:L18, MATCH(B34, INDEX('Case Study II'!I11:L18,,1), 0), 3) | I34: =INDEX('Case Study II'!I11:L18, MATCH(B34, INDEX('Case Study II'!I11:L18,,1), 0), 4) | J34: =C34*E34*I34 | K34: =J34*H34 | L34: =IF(D34='Interview',1,0) | M34: =IF(O34>F34,'Delayed','On time') | N34: =IF(O34>F34,O34-F34,0) | O34: =DATE(2025,3,25)
A35: ='Case Study II'!B44 | B35: ='Case Study II'!I44 | C35: ='Case Study II'!D44 | D35: ='Case Study II'!E44 | E35: ='Case Study II'!F44 | F35: ='Case Study II'!G44 | G35: =INDEX('Case Study II'!I11:L18, MATCH(B35, INDEX('Case Study II'!I11:L18,,1), 0), 2) | H35: =INDEX('Case Study II'!I11:L18, MATCH(B35, INDEX('Case Study II'!I11:L18,,1), 0), 3) | I35: =INDEX('Case Study II'!I11:L18, MATCH(B35, INDEX('Case Study II'!I11:L18,,1), 0), 4) | J35: =C35*E35*I35 | K35: =J35*H35 | L35: =IF(D35='Interview',1,0) | M35: =IF(O35>F35,'Delayed','On time') | N35: =IF(O35>F35,O35-F35,0) | O35: =DATE(2025,3,25)
A36: ='Case Study II'!B45 | B36: ='Case Study II'!I45 | C36: ='Case Study II'!D45 | D36: ='Case Study II'!E45 | E36: ='Case Study II'!F45 | F36: ='Case Study II'!G45 | G36: =INDEX('Case Study II'!I11:L18, MATCH(B36, INDEX('Case Study II'!I11:L18,,1), 0), 2) | H36: =INDEX('Case Study II'!I11:L18, MATCH(B36, INDEX('Case Study II'!I11:L18,,1), 0), 3) | I36: =INDEX('Case Study II'!I11:L18, MATCH(B36, INDEX('Case Study II'!I11:L18,,1), 0), 4) | J36: =C36*E36*I36 | K36: =J36*H36 | L36: =IF(D36='Interview',1,0) | M36: =IF(O36>F36,'Delayed','On time') | N36: =IF(O36>F36,O36-F36,0) | O36: =DATE(2025,3,25)
A37: ='Case Study II'!B46 | B37: ='Case Study II'!I46 | C37: ='Case Study II'!D46 | D37: ='Case Study II'!E46 | E37: ='Case Study II'!F46 | F37: ='Case Study II'!G46 | G37: =INDEX('Case Study II'!I11:L18, MATCH(B37, INDEX('Case Study II'!I11:L18,,1), 0), 2) | H37: =INDEX('Case Study II'!I11:L18, MATCH(B37, INDEX('Case Study II'!I11:L18,,1), 0), 3) | I37: =INDEX('Case Study II'!I11:L18, MATCH(B37, INDEX('Case Study II'!I11:L18,,1), 0), 4) | J37: =C37*E37*I37 | K37: =J37*H37 | L37: =IF(D37='Interview',1,0) | M37: =IF(O37>F37,'Delayed','On time') | N37: =IF(O37>F37,O37-F37,0) | O37: =DATE(2025,3,25)
A38: ='Case Study II'!B47 | B38: ='Case Study II'!I47 | C38: ='Case Study II'!D47 | D38: ='Case Study II'!E47 | E38: ='Case Study II'!F47 | F38: ='Case Study II'!G47 | G38: =INDEX('Case Study II'!I11:L18, MATCH(B38, INDEX('Case Study II'!I11:L18,,1), 0), 2) | H38: =INDEX('Case Study II'!I11:L18, MATCH(B38, INDEX('Case Study II'!I11:L18,,1), 0), 3) | I38: =INDEX('Case Study II'!I11:L18, MATCH(B38, INDEX('Case Study II'!I11:L18,,1), 0), 4) | J38: =C38*E38*I38 | K38: =J38*H38 | L38: =IF(D38='Interview',1,0) | M38: =IF(O38>F38,'Delayed','On time') | N38: =IF(O38>F38,O38-F38,0) | O38: =DATE(2025,3,25)
A39: ='Case Study II'!B48 | B39: ='Case Study II'!I48 | C39: ='Case Study II'!D48 | D39: ='Case Study II'!E48 | E39: ='Case Study II'!F48 | F39: ='Case Study II'!G48 | G39: =INDEX('Case Study II'!I11:L18, MATCH(B39, INDEX('Case Study II'!I11:L18,,1), 0), 2) | H39: =INDEX('Case Study II'!I11:L18, MATCH(B39, INDEX('Case Study II'!I11:L18,,1), 0), 3) | I39: =INDEX('Case Study II'!I11:L18, MATCH(B39, INDEX('Case Study II'!I11:L18,,1), 0), 4) | J39: =C39*E39*I39 | K39: =J39*H39 | L39: =IF(D39='Interview',1,0) | M39: =IF(O39>F39,'Delayed','On time') | N39: =IF(O39>F39,O39-F39,0) | O39: =DATE(2025,3,25)
A40: ='Case Study II'!B49 | B40: ='Case Study II'!I49 | C40: ='Case Study II'!D49 | D40: ='Case Study II'!E49 | E40: ='Case Study II'!F49 | F40: ='Case Study II'!G49 | G40: =INDEX('Case Study II'!I11:L18, MATCH(B40, INDEX('Case Study II'!I11:L18,,1), 0), 2) | H40: =INDEX('Case Study II'!I11:L18, MATCH(B40, INDEX('Case Study II'!I11:L18,,1), 0), 3) | I40: =INDEX('Case Study II'!I11:L18, MATCH(B40, INDEX('Case Study II'!I11:L18,,1), 0), 4) | J40: =C40*E40*I40 | K40: =J40*H40 | L40: =IF(D40='Interview',1,0) | M40: =IF(O40>F40,'Delayed','On time') | N40: =IF(O40>F40,O40-F40,0) | O40: =DATE(2025,3,25)
...

Sheet CS II - Summary
A1: Case Study II – Rewards Dashboard
A3: Country | B3: Local Currency | C3: Total Reward (Local) | D3: Exchange to USD | E3: Total Reward (USD) | F3: Budget Limit (Local) | G3: Budget Limit (USD) | H3: Over Budget?
A4: USA | B4: =INDEX('CS II - Calc'!G:G, MATCH(A4, 'CS II - Calc'!B:B, 0)) | C4: =SUMIF('CS II - Calc'!B:B, A4, 'CS II - Calc'!J:J) | D4: =INDEX('CS II - Calc'!H:H, MATCH(A4, 'CS II - Calc'!B:B, 0)) | E4: =SUMIF('CS II - Calc'!B:B, A4, 'CS II - Calc'!K:K) | F4: 15000 | G4: =D4*F4 | H4: =IF(E4>G4,'YES','NO')
A5: India | B5: =INDEX('CS II - Calc'!G:G, MATCH(A5, 'CS II - Calc'!B:B, 0)) | C5: =SUMIF('CS II - Calc'!B:B, A5, 'CS II - Calc'!J:J) | D5: =INDEX('CS II - Calc'!H:H, MATCH(A5, 'CS II - Calc'!B:B, 0)) | E5: =SUMIF('CS II - Calc'!B:B, A5, 'CS II - Calc'!K:K) | F5: 100000 | G5: =D5*F5 | H5: =IF(E5>G5,'YES','NO')
A6: UK | B6: =INDEX('CS II - Calc'!G:G, MATCH(A6, 'CS II - Calc'!B:B, 0)) | C6: =SUMIF('CS II - Calc'!B:B, A6, 'CS II - Calc'!J:J) | D6: =INDEX('CS II - Calc'!H:H, MATCH(A6, 'CS II - Calc'!B:B, 0)) | E6: =SUMIF('CS II - Calc'!B:B, A6, 'CS II - Calc'!K:K) | F6: 4000 | G6: =D6*F6 | H6: =IF(E6>G6,'YES','NO')
A7: Australia | B7: =INDEX('CS II - Calc'!G:G, MATCH(A7, 'CS II - Calc'!B:B, 0)) | C7: =SUMIF('CS II - Calc'!B:B, A7, 'CS II - Calc'!J:J) | D7: =INDEX('CS II - Calc'!H:H, MATCH(A7, 'CS II - Calc'!B:B, 0)) | E7: =SUMIF('CS II - Calc'!B:B, A7, 'CS II - Calc'!K:K) | F7: 3000 | G7: =D7*F7 | H7: =IF(E7>G7,'YES','NO')
A8: Spain | B8: =INDEX('CS II - Calc'!G:G, MATCH(A8, 'CS II - Calc'!B:B, 0)) | C8: =SUMIF('CS II - Calc'!B:B, A8, 'CS II - Calc'!J:J) | D8: =INDEX('CS II - Calc'!H:H, MATCH(A8, 'CS II - Calc'!B:B, 0)) | E8: =SUMIF('CS II - Calc'!B:B, A8, 'CS II - Calc'!K:K) | F8: 4000 | G8: =D8*F8 | H8: =IF(E8>G8,'YES','NO')
A9: Netherlands | B9: =INDEX('CS II - Calc'!G:G, MATCH(A9, 'CS II - Calc'!B:B, 0)) | C9: =SUMIF('CS II - Calc'!B:B, A9, 'CS II - Calc'!J:J) | D9: =INDEX('CS II - Calc'!H:H, MATCH(A9, 'CS II - Calc'!B:B, 0)) | E9: =SUMIF('CS II - Calc'!B:B, A9, 'CS II - Calc'!K:K) | F9: 4000 | G9: =D9*F9 | H9: =IF(E9>G9,'YES','NO')
A10: Germany | B10: =INDEX('CS II - Calc'!G:G, MATCH(A10, 'CS II - Calc'!B:B, 0)) | C10: =SUMIF('CS II - Calc'!B:B, A10, 'CS II - Calc'!J:J) | D10: =INDEX('CS II - Calc'!H:H, MATCH(A10, 'CS II - Calc'!B:B, 0)) | E10: =SUMIF('CS II - Calc'!B:B, A10, 'CS II - Calc'!K:K) | F10: 4000 | G10: =D10*F10 | H10: =IF(E10>G10,'YES','NO')
A11: Canada | B11: =INDEX('CS II - Calc'!G:G, MATCH(A11, 'CS II - Calc'!B:B, 0)) | C11: =SUMIF('CS II - Calc'!B:B, A11, 'CS II - Calc'!J:J) | D11: =INDEX('CS II - Calc'!H:H, MATCH(A11, 'CS II - Calc'!B:B, 0)) | E11: =SUMIF('CS II - Calc'!B:B, A11, 'CS II - Calc'!K:K) | F11: 2500 | G11: =D11*F11 | H11: =IF(E11>G11,'YES','NO')
A12: OVERALL TOTAL (USD) | E12: =SUM(E4:E11)
A13: Highest Earners
A14: Country | B14: Employee ID | C14: Reward USD
A15: USA | B15: =INDEX('CS II - Calc'!A:A, MATCH(1, ('CS II - Calc'!B:B=A15)*('CS II - Calc'!K:K=C15),0)) | C15: =MAX(IF('CS II - Calc'!B:B=A15, 'CS II - Calc'!K:K))
A16: India | B16: =INDEX('CS II - Calc'!A:A, MATCH(1, ('CS II - Calc'!B:B=A16)*('CS II - Calc'!K:K=C16),0)) | C16: =MAX(IF('CS II - Calc'!B:B=A16, 'CS II - Calc'!K:K))
A17: UK | B17: =INDEX('CS II - Calc'!A:A, MATCH(1, ('CS II - Calc'!B:B=A17)*('CS II - Calc'!K:K=C17),0)) | C17: =MAX(IF('CS II - Calc'!B:B=A17, 'CS II - Calc'!K:K))
A18: Australia | B18: =INDEX('CS II - Calc'!A:A, MATCH(1, ('CS II - Calc'!B:B=A18)*('CS II - Calc'!K:K=C18),0)) | C18: =MAX(IF('CS II - Calc'!B:B=A18, 'CS II - Calc'!K:K))
A19: Spain | B19: =INDEX('CS II - Calc'!A:A, MATCH(1, ('CS II - Calc'!B:B=A19)*('CS II - Calc'!K:K=C19),0)) | C19: =MAX(IF('CS II - Calc'!B:B=A19, 'CS II - Calc'!K:K))
A20: Netherlands | B20: =INDEX('CS II - Calc'!A:A, MATCH(1, ('CS II - Calc'!B:B=A20)*('CS II - Calc'!K:K=C20),0)) | C20: =MAX(IF('CS II - Calc'!B:B=A20, 'CS II - Calc'!K:K))
A21: Germany | B21: =INDEX('CS II - Calc'!A:A, MATCH(1, ('CS II - Calc'!B:B=A21)*('CS II - Calc'!K:K=C21),0)) | C21: =MAX(IF('CS II - Calc'!B:B=A21, 'CS II - Calc'!K:K))
A22: Canada | B22: =INDEX('CS II - Calc'!A:A, MATCH(1, ('CS II - Calc'!B:B=A22)*('CS II - Calc'!K:K=C22),0)) | C22: =MAX(IF('CS II - Calc'!B:B=A22, 'CS II - Calc'!K:K))
A24: Overall Highest (Employee ID) | B24: =INDEX('CS II - Calc'!A:A, MATCH(MAX('CS II - Calc'!K:K), 'CS II - Calc'!K:K, 0))
A25: Overall Highest (Reward USD) | B25: =MAX('CS II - Calc'!K:K)
A26: Interview Totals
A27: Country | B27: Interview Count | C27: Interview Rewards USD
A28: USA | B28: =SUMIFS('CS II - Calc'!L:L, 'CS II - Calc'!B:B, A28) | C28: =SUMIFS('CS II - Calc'!K:K, 'CS II - Calc'!B:B, A28, 'CS II - Calc'!L:L, 1)
A29: India | B29: =SUMIFS('CS II - Calc'!L:L, 'CS II - Calc'!B:B, A29) | C29: =SUMIFS('CS II - Calc'!K:K, 'CS II - Calc'!B:B, A29, 'CS II - Calc'!L:L, 1)
A30: UK | B30: =SUMIFS('CS II - Calc'!L:L, 'CS II - Calc'!B:B, A30) | C30: =SUMIFS('CS II - Calc'!K:K, 'CS II - Calc'!B:B, A30, 'CS II - Calc'!L:L, 1)
A31: Australia | B31: =SUMIFS('CS II - Calc'!L:L, 'CS II - Calc'!B:B, A31) | C31: =SUMIFS('CS II - Calc'!K:K, 'CS II - Calc'!B:B, A31, 'CS II - Calc'!L:L, 1)
A32: Spain | B32: =SUMIFS('CS II - Calc'!L:L, 'CS II - Calc'!B:B, A32) | C32: =SUMIFS('CS II - Calc'!K:K, 'CS II - Calc'!B:B, A32, 'CS II - Calc'!L:L, 1)
A33: Netherlands | B33: =SUMIFS('CS II - Calc'!L:L, 'CS II - Calc'!B:B, A33) | C33: =SUMIFS('CS II - Calc'!K:K, 'CS II - Calc'!B:B, A33, 'CS II - Calc'!L:L, 1)
A34: Germany | B34: =SUMIFS('CS II - Calc'!L:L, 'CS II - Calc'!B:B, A34) | C34: =SUMIFS('CS II - Calc'!K:K, 'CS II - Calc'!B:B, A34, 'CS II - Calc'!L:L, 1)
A35: Canada | B35: =SUMIFS('CS II - Calc'!L:L, 'CS II - Calc'!B:B, A35) | C35: =SUMIFS('CS II - Calc'!K:K, 'CS II - Calc'!B:B, A35, 'CS II - Calc'!L:L, 1)
A36: Overall Interview Count | B36: =SUM(B28:B35)
A37: Overall Interview Rewards USD | B37: =SUM(C28:C35)
